Workbook

Sheet Sheet1
A1: Date | B1: Username | C1: JobName | D1: SubJobName | E1: StartTime | F1: EndTime | G1: Hrs | H1: Description | I1: Tag | J1: Maintenance | K1: CMT Testing | L1: New Request
A2: 46204 | B2: Benjie | C2: TBS_PRG | D2: JUN2026 | E2: 1.5569444 | F2: 1.5756944 | G2: 0.45 | H2: JUN2026: cont. adjusting the import template sheet | I2: New | L2: =IF(I2="New",G2,0) -> 0.45
A3: 46204 | B3: Reymart | C3: TBS_CALENDAR | D3: MAINTENANCE | E3: 1.4465278 | F3: 1.5340278 | G3: 2.1 | H3: Bug Fix: Filing Type - FT_055 -Audit: Created By / Date captured, Action By was not captured | J3: =IF(I3="New",0,G3-K3) -> 0.6 | K3: 1.5 | L3: =IF(I3="New",G3,0) -> 0
A4: 46204 | B4: Reymart | C4: TBS_CALENDAR | D4: MAINTENANCE | E4: 1.7541667 | F4: 1.8451389 | G4: 2.183333 | H4: Bug Fix: Holiday - HOL_008 - Delete unused holiday Deleted unused holiday still appears in the holiday list | J4: =IF(I4="New",0,G4-K4) -> 1.383333 | K4: 0.8 | L4: =IF(I4="New",G4,0) -> 0
A5: 46204 | B5: Reymart | C5: TBS_CALENDAR | D5: MAINTENANCE | E5: 1.5340278 | F5: 1.6208333 | G5: 2.083333 | H5: Bug Fix: Filing Type - FT_056 - Audit: Updated By / Date captured Action By was not captured | J5: =IF(I5="New",0,G5-K5) -> 1.083333 | K5: 1 | L5: =IF(I5="New",G5,0) -> 0
A6: 46204 | B6: Reymart | C6: TBS_CALENDAR | D6: MAINTENANCE | E6: 1.6652778 | F6: 1.7541667 | G6: 2.133333 | H6: Bug Fix: State - ST_016 - Cities are displayed in a single continuous list without pagination features | J6: =IF(I6="New",0,G6-K6) -> 0.533333 | K6: 1.6 | L6: =IF(I6="New",G6,0) -> 0
A7: 46205 | B7: Reymart | C7: TBS_CALENDAR | D7: MAINTENANCE | E7: 1.5305556 | F7: 1.6194444 | G7: 2.133333 | H7: Bug Fix: UL-008 - The system successfully generates a new temporary password, but it fails to mask it by default | J7: =IF(I7="New",0,G7-K7) -> 0.633333 | K7: 1.5 | L7: =IF(I7="New",G7,0) -> 0
A8: 46205 | B8: Reymart | C8: TBS_CALENDAR | D8: MAINTENANCE | E8: 1.6652778 | F8: 1.7534722 | G8: 2.116666 | H8: Bug Fix: Users List - UL-012 - Agent role – assign Processor/Preparer/Filer | J8: =IF(I8="New",0,G8-K8) -> 0.716666 | K8: 1.4 | L8: =IF(I8="New",G8,0) -> 0
A9: 46205 | B9: Reymart | C9: TBS_CALENDAR | D9: MAINTENANCE | E9: 1.4402778 | F9: 1.5305556 | G9: 2.166666 | H9: Bug Fix: Holiday - HOL_010 - Audit tracking on add/edit/delete/clone | J9: =IF(I9="New",0,G9-K9) -> 0.966666 | K9: 1.2 | L9: =IF(I9="New",G9,0) -> 0
A10: 46205 | B10: Reymart | C10: TBS_CALENDAR | D10: MAINTENANCE | E10: 1.7534722 | F10: 1.8465278 | G10: 2.233333 | H10: Bug Fix: Users List - UL-013 - Assistant Manager role assignment, Data Display Mismatch users filing roles | J10: =IF(I10="New",0,G10-K10) -> 0.633333 | K10: 1.6 | L10: =IF(I10="New",G10,0) -> 0
A11: 46206 | B11: Reymart | C11: TBS_CALENDAR | D11: MAINTENANCE | E11: 1.5659722 | F11: 1.6541667 | G11: 2.116666 | H11: Bug Fix: UL-016 Supervisor role assignment - The Users Search Result grid incorrectly displays "Processor" in list | J11: =IF(I11="New",0,G11-K11) -> 0.816666 | K11: 1.3 | L11: =IF(I11="New",G11,0) -> 0
A12: 46206 | B12: Reymart | C12: TBS_CALENDAR | D12: MAINTENANCE | E12: 1.7041667 | F12: 1.7909722 | G12: 2.083333 | H12: Bug Fix: ST_021 - States - Add / Edit / Delete - Delete City was not captured | J12: =IF(I12="New",0,G12-K12) -> 0.883333 | K12: 1.2 | L12: =IF(I12="New",G12,0) -> 0
A13: 46206 | B13: Reymart | C13: TBS_CALENDAR | D13: MAINTENANCE | E13: 1.4756944 | F13: 1.5659722 | G13: 2.166666 | H13: Bug Fix: UL-015 - The Users Search Result grid incorrectly displays "Processor" in the user's filing role list | J13: =IF(I13="New",0,G13-K13) -> 1.466666 | K13: 0.7 | L13: =IF(I13="New",G13,0) -> 0
A14: 46206 | B14: Reymart | C14: TBS_CALENDAR | D14: MAINTENANCE | E14: 1.7909722 | F14: 1.8791667 | G14: 2.116666 | H14: Bug Fix: Filing Type - FT_020 - Start date did not automatically change after changing the frequency | J14: =IF(I14="New",0,G14-K14) -> 1.416666 | K14: 0.7 | L14: =IF(I14="New",G14,0) -> 0
... A18: 46209 | B18: Reymart | C18: TBS_CALENDAR | D18: 2026JULY | E18: 1.4756944 | F18: 1.5638889 | G18: 2.116666 | H18: Bug Fix: ST - City - Delete City was not captured | J18: =IF(I18="New",0,G18-K18) -> 1.316666 | K18: 0.8 | L18: =IF(I18="New",G18,0) -> 0
A19: 46209 | B19: Benjie | C19: TBS_PRG | D19: 2026JUL | E19: 1.6895833 | F19: 1.7284722 | G19: 0.933333 | H19: 2026JUL: work on the adjustment for setting up the template sheet. | I19: New | L19: =IF(I19="New",G19,0) -> 0.933333
A20: 46209 | B20: Benjie | C20: TBS_PRG | D20: 2026JUL | E20: 1.7284722 | F20: 1.7729167 | G20: 1.066666 | H20: 2026JUL: cont.. working on the adjustment for setting up the template sheet. | I20: New | L20: =IF(I20="New",G20,0) -> 1.066666
A21: 46209 | B21: Benjie | C21: TBS_PRG | D21: 2026JUL | E21: 1.8368056 | F21: 1.8902778 | G21: 1.283333 | H21: 2026JUL: cont.. working on the adjustment for setting up the template sheet. | I21: New | L21: =IF(I21="New",G21,0) -> 1.283333
A22: 46210 | B22: Benjie | C22: TBS_PRG | D22: 2026JUL | E22: 1.7486111 | F22: 1.7708333 | G22: 0.533333 | H22: 2026JUL: JUN2026: working on the displaying of state, from states module and its interaction with others | I22: New | L22: =IF(I22="New",G22,0) -> 0.533333
A23: 46210 | B23: Benjie | C23: TBS_PRG | D23: 2026JUL | E23: 1.8631944 | F23: 1.9083333 | G23: 1.083333 | H23: 2026JUL: Work on the affected parts when only allowing to display the state with tax rates on other modules | I23: New | L23: =IF(I23="New",G23,0) -> 1.083333
A24: 46210 | B24: Benjie | C24: TBS_PRG | D24: 2026JUL | E24: 1.9083333 | F24: 1.9520833 | G24: 1.05 | H24: 2026JUL: Cont.. working on the affected parts when only allowing to display the state with tax rates on other modules | I24: New | L24: =IF(I24="New",G24,0) -> 1.05
A25: 46210 | B25: Benjie | C25: TBS_PRG | D25: 2026JUL | E25: 1.9520833 | F25: 1.9993056 | G25: 1.133333 | H25: 2026JUL: Cont.. working on the affected parts when only allowing to display the state with tax rates on other modules | I25: New | L25: =IF(I25="New",G25,0) -> 1.133333
A26: 46210 | B26: Reymart | C26: TBS_CALENDAR | D26: 2026JULY | E26: 1.5236111 | F26: 1.6125 | G26: 2.133333 | H26: Bug Fix: FT - Filing Types - Removed the validation for detecting existing forms when importing new forms and filings | J26: =IF(I26="New",0,G26-K26) -> 1.433333 | K26: 0.7 | L26: =IF(I26="New",G26,0) -> 0
A27: 46210 | B27: Reymart | C27: TBS_CALENDAR | D27: 2026JULY | E27: 1.6645833 | F27: 1.7548611 | G27: 2.166666 | H27: Bug Fix: Sales & Use Tax - CST/RVWS Gross Allocation - Enabled the Total Amount field for Managers role | J27: =IF(I27="New",0,G27-K27) -> 1.266666 | K27: 0.9 | L27: =IF(I27="New",G27,0) -> 0
A28: 46210 | B28: Reymart | C28: TBS_CALENDAR | D28: 2026JULY | E28: 1.4319444 | F28: 1.5236111 | G28: 2.2 | H28: Bug Fix: FT Filing Types - When importing filings for other BU, error message saying form already exists was encountered | J28: =IF(I28="New",0,G28-K28) -> 0.9 | K28: 1.3 | L28: =IF(I28="New",G28,0) -> 0
A29: 46210 | B29: Reymart | C29: TBS_CALENDAR | D29: 2026JULY | E29: 1.7548611 | F29: 1.8402778 | G29: 2.05 | H29: Bug Fix: Filing Website - Enhanced the import process to support updating existing data using the re-import process | J29: =IF(I29="New",0,G29-K29) -> 1.35 | K29: 0.7 | L29: =IF(I29="New",G29,0) -> 0
A30: 46211 | B30: Benjie | C30: TBS_PRG | D30: 2026JUL | E30: 1.4673611 | F30: 1.4944444 | G30: 0.65 | H30: Worked on the committing of changes. Aggregate similar changes. | J30: =IF(I30="New",0,G30-K30) -> 0.65 | L30: =IF(I30="New",G30,0) -> 0
A31: 46211 | B31: Reymart | C31: TBS_CALENDAR | D31: 2026JULY | E31: 1.7395833 | F31: 1.8305556 | G31: 2.183333 | H31: Bug Fix: FT_020 - Added function 'processMonthAndDayValuesForSavingEditForm' that get the exact date | J31: =IF(I31="New",0,G31-K31) -> 1.383333 | K31: 0.8 | L31: =IF(I31="New",G31,0) -> 0
A32: 46211 | B32: Benjie | C32: TBS_PRG | D32: 2026JUL | E32: 1.0111111 | F32: 1.0520833 | G32: 0.983333 | H32: 2026JUL: Cont.. working on the affected parts when only allowing to display the state with tax rates on other modules | I32: New | L32: =IF(I32="New",G32,0) -> 0.983333
A33: 46211 | B33: Reymart | C33: TBS_CALENDAR | D33: 2026JULY | E33: 1.5131944 | F33: 1.6006944 | G33: 2.1 | H33: Bug Fix: FT_020 - Added new sections for date fields based on the selected frequency. | J33: =IF(I33="New",0,G33-K33) -> 0.8 | K33: 1.3 | L33: =IF(I33="New",G33,0) -> 0
A34: 46211 | B34: Reymart | C34: TBS_CALENDAR | D34: 2026JULY | E34: 1.6520833 | F34: 1.7395833 | G34: 2.1 | H34: Bug Fix: FT_020 - Added function 'loadFilingPeriodEditForm_change' that properly populates dates based on frequency | J34: =IF(I34="New",0,G34-K34) -> 0.8 | K34: 1.3 | L34: =IF(I34="New",G34,0) -> 0
A35: 46211 | B35: Reymart | C35: TBS_CALENDAR | D35: 2026JULY | E35: 1.4236111 | F35: 1.5131944 | G35: 2.15 | H35: Bug Fix: FT_020 - Start Date recalculated by Frequency | J35: =IF(I35="New",0,G35-K35) -> 0.55 | K35: 1.6 | L35: =IF(I35="New",G35,0) -> 0
A36: 46211 | B36: Benjie | C36: TBS_PRG | D36: 2026JUL | E36: 1.5611111 | F36: 1.6486111 | G36: 2.1 | H36: 2026JUL: working on the fix for locking of invoices. Change the locking on completed invoices. | I36: New | L36: =IF(I36="New",G36,0) -> 2.1
A37: 46211 | B37: Benjie | C37: TBS_PRG | D37: 2026JUL | E37: 1.7805556 | F37: 1.8034722 | G37: 0.55 | H37: 2026JUL: working on the assignment issue on the define jurisdiction name for geocode and tax category. | I37: New | L37: =IF(I37="New",G37,0) -> 0.55
A38: 46211 | B38: Benjie | C38: TBS_PRG | D38: 2026JUL | E38: 1.8958333 | F38: 1.9166667 | G38: 0.5 | H38: 2026JUL: development update meeting on synergy with tbs and binc team. | J38: =IF(I38="New",0,G38-K38) -> 0.5 | L38: =IF(I38="New",G38,0) -> 0
A39: 46212 | B39: Reymart | C39: TBS_CALENDAR | D39: 2026JULY | E39: 1.6715278 | F39: 1.7590278 | G39: 2.1 | H39: Bug Fix: Import Gross and Tax Amount - Enhanced the function 'getState' and ensured they are trimmed before being used | J39: =IF(I39="New",0,G39-K39) -> 1 | K39: 1.1 | L39: =IF(I39="New",G39,0) -> 0
A40: 46212 | B40: Benjie | C40: TBS_PRG | D40: 2026JUL | E40: 1.1152778 | F40: 1.1645833 | G40: 1.183333 | H40: 2026JUL: Reviewing the issue on discrepancy the zainab sent this is for the nov 2024 | J40: =IF(I40="New",0,G40-K40) -> 1.183333 | L40: =IF(I40="New",G40,0) -> 0
A41: 46212 | B41: Benjie | C41: TBS_PRG | D41: 2026JUL | E41: 1.1013889 | F41: 1.1152778 | G41: 0.333333 | H41: 2026JUL: working on the ngtypeahead of the dropdown. | J41: 0.333333 | L41: =IF(I41="New",G41,0) -> 0
A42: 46212 | B42: Benjie | C42: TBS_PRG | D42: 2026JUL | E42: 1.6069444 | F42: 1.64375 | G42: 0.883333 | H42: Cont. reviewing the 12-2024, 03-2025 & 05-2025 period mentioned that has some discrepancy. | J42: =IF(I42="New",0,G42-K42) -> 0.883333 | L42: =IF(I42="New",G42,0) -> 0
A43: 46212 | B43: Reymart | C43: TBS_CALENDAR | D43: 2026JULY | E43: 1.5784722 | F43: 1.6715278 | G43: 2.233333 | H43: Conducted debugging in the DevTools section of main.js in CMT Tax Calendar test site 8091 to capture the exact issue | J43: =IF(I43="New",0,G43-K43) -> 1.033333 | K43: 1.2 | L43: =IF(I43="New",G43,0) -> 0
...

Sheet Sheet2
A1: Date
A2: 46204 | B2: =SUMIFS(Sheet1!G:G,Sheet1!B:B,"=Reymart",Sheet1!A:A,Sheet2!A2) -> 8.499999
A3: 46205 | B3: =SUMIFS(Sheet1!G:G,Sheet1!B:B,"=Reymart",Sheet1!A:A,Sheet2!A3) -> 8.649998
A4: 46206 | B4: =SUMIFS(Sheet1!G:G,Sheet1!B:B,"=Reymart",Sheet1!A:A,Sheet2!A4) -> 8.483331
A5: 46209 | B5: =SUMIFS(Sheet1!G:G,Sheet1!B:B,"=Reymart",Sheet1!A:A,Sheet2!A5) -> 8.633331
A6: 46210 | B6: =SUMIFS(Sheet1!G:G,Sheet1!B:B,"=Reymart",Sheet1!A:A,Sheet2!A6) -> 8.549999
A7: 46211 | B7: =SUMIFS(Sheet1!G:G,Sheet1!B:B,"=Reymart",Sheet1!A:A,Sheet2!A7) -> 8.533333
A8: 46212 | B8: =SUMIFS(Sheet1!G:G,Sheet1!B:B,"=Reymart",Sheet1!A:A,Sheet2!A8) -> 4.333333
A9: 46213 | B9: =SUMIFS(Sheet1!G:G,Sheet1!B:B,"=Reymart",Sheet1!A:A,Sheet2!A9) -> 0
A10: 46214 | B10: =SUMIFS(Sheet1!G:G,Sheet1!B:B,"=Reymart",Sheet1!A:A,Sheet2!A10) -> 0
A11: 46216 | B11: =SUMIFS(Sheet1!G:G,Sheet1!B:B,"=Reymart",Sheet1!A:A,Sheet2!A11) -> 4.233333
A12: 46217 | B12: =SUMIFS(Sheet1!G:G,Sheet1!B:B,"=Reymart",Sheet1!A:A,Sheet2!A12) -> 8.366665
A13: 46218 | B13: =SUMIFS(Sheet1!G:G,Sheet1!B:B,"=Reymart",Sheet1!A:A,Sheet2!A13) -> 8.449999
... A25: 46234 | B25: =SUMIFS(Sheet1!G:G,Sheet1!B:B,"=Reymart",Sheet1!A:A,Sheet2!A25) -> 4.149999
